Workbook

Sheet 3Stmt
A1: Auto Partner S.A. 3-Statement Model
A2: Figures in PLN millions, except per-share data | B2: 2022 Opening BS | C2: 2023A | D2: 2024A | E2: 2025A | F2: 2026E | G2: 2027E | H2: 2028E | I2: 2029E | J2: 2030E
A3: Income Statement
A4: Revenue | B4: 2834.701 | C4: 3653.384 | D4: 4112.497 | E4: 4424.895 | F4: =E4*(1+Assumptions!E$4) -> 4889.509 | G4: =F4*(1+Assumptions!F$4) -> 5280.6697 | H4: =G4*(1+Assumptions!G$4) -> 5623.9132 | I4: =H4*(1+Assumptions!H$4) -> 5933.2285 | J4: =I4*(1+Assumptions!I$4) -> 6200.2237
A5: Revenue Growth | C5: =C4/B4-1 -> 0.28880753 | D5: =D4/C4-1 -> 0.12566787 | E5: =E4/D4-1 -> 0.075963095 | F5: =F4/E4-1 -> 0.105 | G5: =G4/F4-1 -> 0.08 | H5: =H4/G4-1 -> 0.065 | I5: =I4/H4-1 -> 0.055 | J5: =J4/I4-1 -> 0.045
A6: COGS | C6: 2663.505 | D6: 2985.276 | E6: 3249.797 | F6: =F4-F7 -> 3544.894 | G6: =G4-G7 -> 3839.0469 | H6: =H4-H7 -> 4094.2088 | I6: =I4-I7 -> 4319.3903 | J6: =J4-J7 -> 4513.7629
A7: Gross Profit | C7: =C4-C6 -> 989.879 | D7: =D4-D6 -> 1127.221 | E7: =E4-E6 -> 1175.098 | F7: =F4*Assumptions!E$5 -> 1344.615 | G7: =G4*Assumptions!F$5 -> 1441.6228 | H7: =H4*Assumptions!G$5 -> 1529.7044 | I7: =I4*Assumptions!H$5 -> 1613.8381 | J7: =J4*Assumptions!I$5 -> 1686.4609
A8: Gross Margin | C8: =C7/C4 -> 0.27094852 | D8: =D7/D4 -> 0.27409649 | E8: =E7/E4 -> 0.26556517 | F8: =F7/F4 -> 0.275 | G8: =G7/G4 -> 0.273 | H8: =H7/H4 -> 0.272 | I8: =I7/I4 -> 0.272 | J8: =J7/J4 -> 0.272
A9: EBITDA | C9: 346.228 | D9: 343.556 | E9: 337.206 | F9: =F4*Assumptions!E$6 -> 400.93974 | G9: =G4*Assumptions!F$6 -> 438.29558 | H9: =H4*Assumptions!G$6 -> 472.40871 | I9: =I4*Assumptions!H$6 -> 504.32442 | J9: =J4*Assumptions!I$6 -> 527.01902
A10: EBITDA Margin | C10: =C9/C4 -> 0.094769124 | D10: =D9/D4 -> 0.083539514 | E10: =E9/E4 -> 0.076206554 | F10: =F9/F4 -> 0.082 | G10: =G9/G4 -> 0.083 | H10: =H9/H4 -> 0.084 | I10: =I9/I4 -> 0.085 | J10: =J9/J4 -> 0.085
A11: Depreciation & Amortization | C11: 43.504 | D11: 54.284 | E11: 56.86 | F11: =F4*Assumptions!E$7 -> 63.563617 | G11: =G4*Assumptions!F$7 -> 68.648706 | H11: =H4*Assumptions!G$7 -> 73.110872 | I11: =I4*Assumptions!H$7 -> 77.13197 | J11: =J4*Assumptions!I$7 -> 80.602908
A12: EBIT | C12: =C9-C11 -> 302.724 | D12: =D9-D11 -> 289.272 | E12: =E9-E11 -> 280.346 | F12: =F9-F11 -> 337.37612 | G12: =G9-G11 -> 369.64688 | H12: =H9-H11 -> 399.29784 | I12: =I9-I11 -> 427.19245 | J12: =J9-J11 -> 446.41611
A13: EBIT Margin | C13: =C12/C4 -> 0.08286126 | D13: =D12/D4 -> 0.070339747 | E13: =E12/E4 -> 0.063356532 | F13: =F12/F4 -> 0.069 | G13: =G12/G4 -> 0.07 | H13: =H12/H4 -> 0.071 | I13: =I12/I4 -> 0.072 | J13: =J12/J4 -> 0.072
A14: Net Interest Expense | C14: 25.469 | D14: 30.642 | E14: 32.771 | F14: =E30*Assumptions!E$16 -> 38.36166 | G14: =F30*Assumptions!F$16 -> 34.460975 | H14: =G30*Assumptions!G$16 -> 25.777893 | I14: =H30*Assumptions!H$16 -> 13.845477 | J14: =I30*Assumptions!I$16 -> 0.86933056
A15: EBT | C15: =C12-C14 -> 277.255 | D15: =D12-D14 -> 258.63 | E15: =E12-E14 -> 247.575 | F15: =F12-F14 -> 299.01446 | G15: =G12-G14 -> 335.1859 | H15: =H12-H14 -> 373.51995 | I15: =I12-I14 -> 413.34697 | J15: =J12-J14 -> 445.54678
A16: Taxes | C16: =C15-C17 -> 53.669 | D16: =D15-D17 -> 50.654 | E16: =E15-E17 -> 48.643 | F16: =F15*Assumptions!E$15 -> 58.606834 | G16: =G15*Assumptions!F$15 -> 65.696437 | H16: =H15*Assumptions!G$15 -> 73.209909 | I16: =I15*Assumptions!H$15 -> 81.016006 | J16: =J15*Assumptions!I$15 -> 87.327168
A17: Net Income | C17: 223.586 | D17: 207.976 | E17: 198.932 | F17: =F15-F16 -> 240.40763 | G17: =G15-G16 -> 269.48947 | H17: =H15-H16 -> 300.31004 | I17: =I15-I16 -> 332.33096 | J17: =J15-J16 -> 358.21961
A18: Net Margin | C18: =C17/C4 -> 0.061199699 | D18: =D17/D4 -> 0.050571709 | E18: =E17/E4 -> 0.044957451 | F18: =F17/F4 -> 0.049168051 | G18: =G17/G4 -> 0.051033199 | H18: =H17/H4 -> 0.053398768 | I18: =I17/I4 -> 0.056011827 | J18: =J17/J4 -> 0.057775272
A19: EPS | C19: =C17/Assumptions!$B$22 -> 1.7117287 | D19: =D17/Assumptions!$B$22 -> 1.5922217 | E19: =E17/Assumptions!$B$22 -> 1.5229827 | F19: =F17/Assumptions!$B$22 -> 1.8405116 | G19: =G17/Assumptions!$B$22 -> 2.0631562 | H19: =H17/Assumptions!$B$22 -> 2.2991122 | I19: =I17/Assumptions!$B$22 -> 2.5442579 | J19: =J17/Assumptions!$B$22 -> 2.7424561
A20: Balance Sheet
A21: Cash | B21: 34.931 | C21: 37.36 | D21: 38.584 | E21: 51.588 | F21: =F46 -> 97.79018 | G21: =G46 -> 105.61339 | H21: =H46 -> 112.47826 | I21: =I46 -> 118.66457 | J21: =J46 -> 329.48585
A22: Accounts Receivable | B22: 281.343 | C22: 357.031 | D22: 420.89 | E22: 497.091 | F22: =F4*Assumptions!E$10/365 -> 542.53456 | G22: =G4*Assumptions!F$10/365 -> 578.70353 | H22: =H4*Assumptions!G$10/365 -> 608.61527 | I22: =I4*Assumptions!H$10/365 -> 633.9614 | J22: =J4*Assumptions!I$10/365 -> 653.9962
A23: Inventory | B23: 955.73 | C23: 1006.367 | D23: 1120.151 | E23: 1195.105 | F23: =F6*Assumptions!E$11/365 -> 1281.9891 | G23: =G6*Assumptions!F$11/365 -> 1367.3318 | H23: =H6*Assumptions!G$11/365 -> 1435.7773 | I23: =I6*Assumptions!H$11/365 -> 1502.9111 | J23: =J6*Assumptions!I$11/365 -> 1558.1757
A24: Other Current Assets | B24: 13.588 | C24: 20.623 | D24: 23.821 | E24: 22.044 | F24: =F4*Assumptions!E$13 -> 24.447545 | G24: =G4*Assumptions!F$13 -> 26.403348 | H24: =H4*Assumptions!G$13 -> 28.119566 | I24: =I4*Assumptions!H$13 -> 29.666142 | J24: =J4*Assumptions!I$13 -> 31.001119
A25: Total Current Assets | B25: =SUM(B21:B24) -> 1285.592 | C25: =SUM(C21:C24) -> 1421.381 | D25: =SUM(D21:D24) -> 1603.446 | E25: =SUM(E21:E24) -> 1765.828 | F25: =SUM(F21:F24) -> 1946.7613 | G25: =SUM(G21:G24) -> 2078.052 | H25: =SUM(H21:H24) -> 2184.9904 | I25: =SUM(I21:I24) -> 2285.2033 | J25: =SUM(J21:J24) -> 2572.6588
A26: PP&E & Intangibles, Net | B26: 278.123 | C26: 366.904 | D26: 416.201 | E26: 558.127 | F26: =E26-F42-F11 -> 558.127 | G26: =F26-G42-G11 -> 552.84633 | H26: =G26-H42-H11 -> 541.5985 | I26: =H26-I42-I11 -> 529.73205 | J26: =I26-J42-J11 -> 517.3316
A27: Other Non-Current Assets | B27: 6.567 | C27: 5.638 | D27: 6.28 | E27: 6.647 | F27: =E27 -> 6.647 | G27: =F27 -> 6.647 | H27: =G27 -> 6.647 | I27: =H27 -> 6.647 | J27: =I27 -> 6.647
A28: Total Assets | B28: =SUM(B25:B27) -> 1570.282 | C28: =SUM(C25:C27) -> 1793.923 | D28: =SUM(D25:D27) -> 2025.927 | E28: =SUM(E25:E27) -> 2330.602 | F28: =SUM(F25:F27) -> 2511.5353 | G28: =SUM(G25:G27) -> 2637.5454 | H28: =SUM(H25:H27) -> 2733.2359 | I28: =SUM(I25:I27) -> 2821.5823 | J28: =SUM(J25:J27) -> 3096.6374
A29: Accounts Payable | B29: 130.215 | C29: 154.107 | D29: 145.142 | E29: 145.053 | F29: =F6*Assumptions!E$12/365 -> 160.24863 | G29: =G6*Assumptions!F$12/365 -> 176.70134 | H29: =H6*Assumptions!G$12/365 -> 190.68918 | I29: =I6*Assumptions!H$12/365 -> 203.54387 | J29: =J6*Assumptions!I$12/365 -> 216.41329
A30: Debt & Lease Liabilities (simplified) | B30: 500.932 | C30: 490 | D30: 526.613 | E30: 639.361 | F30: =E30+F44 -> 574.34958 | G30: =F30+G44 -> 429.63155 | H30: =G30+H44 -> 230.75795 | I30: =H30+I44 -> 14.488843 | J30: =I30+J44 -> 0
A31: Other Liabilities | B31: 96.311 | C31: 103.624 | D31: 119.879 | E31: 132.303 | F31: =F4*Assumptions!E$14 -> 146.68527 | G31: =G4*Assumptions!F$14 -> 158.42009 | H31: =H4*Assumptions!G$14 -> 168.7174 | I31: =I4*Assumptions!H$14 -> 177.99685 | J31: =J4*Assumptions!I$14 -> 186.00671
A32: Total Liabilities | B32: =SUM(B29:B31) -> 727.458 | C32: =SUM(C29:C31) -> 747.731 | D32: =SUM(D29:D31) -> 791.634 | E32: =SUM(E29:E31) -> 916.717 | F32: =SUM(F29:F31) -> 881.28348 | G32: =SUM(G29:G31) -> 764.75298 | H32: =SUM(H29:H31) -> 590.16453 | I32: =SUM(I29:I31) -> 396.02957 | J32: =SUM(J29:J31) -> 402.42
A33: Shareholders' Equity | B33: 842.824 | C33: 1046.192 | D33: 1234.293 | E33: 1413.885 | F33: =E33+F37+F43 -> 1630.2519 | G33: =F33+G37+G43 -> 1872.7924 | H33: =G33+H37+H43 -> 2143.0714 | I33: =H33+I37+I43 -> 2425.5527 | J33: =I33+J37+J43 -> 2694.2174
A34: Total Liabilities & Equity | B34: =B32+B33 -> 1570.282 | C34: =C32+C33 -> 1793.923 | D34: =D32+D33 -> 2025.927 | E34: =E32+E33 -> 2330.602 | F34: =F32+F33 -> 2511.5353 | G34: =G32+G33 -> 2637.5454 | H34: =H32+H33 -> 2733.2359 | I34: =I32+I33 -> 2821.5823 | J34: =J32+J33 -> 3096.6374
A35: Balance Sheet Check | B35: =B28-B34 -> 0 | C35: =C28-C34 -> 0 | D35: =D28-D34 -> 0 | E35: =E28-E34 -> 0 | F35: =F28-F34 -> 0 | G35: =G28-G34 -> 0 | H35: =H28-H34 -> 0 | I35: =I28-I34 -> 0 | J35: =J28-J34 -> 0
A36: Cash Flow Statement
A37: Net Income | C37: =C17 -> 223.586 | D37: =D17 -> 207.976 | E37: =E17 -> 198.932 | F37: =F17 -> 240.40763 | G37: =G17 -> 269.48947 | H37: =H17 -> 300.31004 | I37: =I17 -> 332.33096 | J37: =J17 -> 358.21961
A38: D&A | C38: =C11 -> 43.504 | D38: =D11 -> 54.284 | E38: =E11 -> 56.86 | F38: =F11 -> 63.563617 | G38: =G11 -> 68.648706 | H38: =H11 -> 73.110872 | I38: =I11 -> 77.13197 | J38: =J11 -> 80.602908
A39: Working Capital | B39: =B22+B23+B24-B29-B31 -> 1024.135 | C39: =C22+C23+C24-C29-C31 -> 1126.29 | D39: =D22+D23+D24-D29-D31 -> 1299.841 | E39: =E22+E23+E24-E29-E31 -> 1436.884 | F39: =F22+F23+F24-F29-F31 -> 1542.0373 | G39: =G22+G23+G24-G29-G31 -> 1637.3172 | H39: =H22+H23+H24-H29-H31 -> 1713.1056 | I39: =I22+I23+I24-I29-I31 -> 1784.998 | J39: =J22+J23+J24-J29-J31 -> 1840.753
A40: Change in Working Capital | C40: =C39-B39 -> 102.155 | D40: =D39-C39 -> 173.551 | E40: =E39-D39 -> 137.043 | F40: =F39-E39 -> 105.15327 | G40: =G39-F39 -> 95.279946 | H40: =H39-G39 -> 75.788388 | I40: =I39-H39 -> 71.892363 | J40: =J39-I39 -> 55.755035
...

Sheet Cover
A1: Auto Partner S.A. Equity Research Project
A2: 3-Statement Model, DCF & Comparable Valuation
A3: Company | B3: Auto Partner S.A.
A4: Ticker | B4: APR.WA / WSE
A5: Currency / Units | B5: PLN mm; share prices in PLN
A6: Prepared for | B6: Portfolio project
A7: As of | B7: 46219
A8: Base Case Snapshot
A9: Current Share Price | B9: =Assumptions!B21 -> 24.9
A10: DCF Implied Share Price | B10: =DCF!B24 -> 27.368409
A11: Comps Implied Share Price | B11: =Comps!B27 -> 22.395188
A12: DCF Upside / (Downside) | B12: =B10/B9-1 -> 0.099132907
A13: Recommendation Framing | B13: =IF(B12>15%,"Positive / further diligence",IF(B12<-10%,"Cautious / downside risk","Neutral / watchlist")) -> Neutral / watchlist
A14: Key Sources | B14: Official filings + IR + market data
A15: Model Status | B15: Draft v1 - ready for refinement
A16: Portfolio Project Flow
A17: 1 | B17: Understand company and source historical data
A18: 2 | B18: Build 3-statement historical model and operating forecast
A19: 3 | B19: Value company using DCF with WACC and terminal value
A20: 4 | B20: Cross-check valuation using comparable company multiples
A21: 5 | B21: Run checks, explain assumptions, and document sources
A22: Investment Thesis
A23: Growth | B23: Solid revenue growth supported by historical execution and Jan-May 2026 sales momentum.
A24: Margins | B24: Q1 2026 margin improvement may support FY26 EBITDA margin rebound if sustained.
A25: Operations | B25: Zgorzelec logistics hub may improve efficiency but adds cost base
A26: Risks | B26: Working-capital intensity, inventory turns, EUR/PLN, competition
A27: Cash Flow | B27: Working-capital intensity remains a key constraint to FCF conversion.
A28: Valuation | B28: DCF implies modest upside, while comps imply downside.

Sheet Sources
A1: Sources & Provenance Log
A3: Item | B3: Period / As-of | C3: Source URL | D3: Accessed
A4: FY2025 income statement / balance sheet / cash flow | B4: FY2025 | C4: https://autopartner.com/wp-content/uploads/2026/04/SSFY2025_EN.pdf | D4: 46207
A5: FY2024 and FY2023 historical financials | B5: FY2024/FY2023 | C5: https://autopartner.com/wp-content/uploads/2025/04/SSFY2024_EN-1.pdf | D5: 46207
A6: Historical KPI table | B6: 2023-2025 | C6: https://ir.autopartner.com/en/materials-for-investors/ | D6: 46207
A7: Q1 2026 preliminary results | B7: 1Q 2026 | C7: https://autopartner.com/wp-content/uploads/2026/05/Current-Report-No.-9-Inside-information-%E2%80%93-preliminary-estimates-of-consolidated-results-for-Q1-2026.pdf | D7: 46207
A8: May 2026 revenue update | B8: May 2026 / YTD | C8: https://autopartner.com/wp-content/uploads/2026/06/Current-Report-No-16-Inside-information-%E2%80%93-Monthly-revenue-report-for-May-2026.pdf | D8: 46207
A9: Current share price | B9: 46203 | C9: https://ir.autopartner.com/en/stock-market-information/ | D9: 46207
A10: Poland 10Y government bond yield | B10: 46203 | C10: https://tradingeconomics.com/poland/government-bond-yield | D10: 46207
A11: Poland standard CIT rate | B11: 2026 | C11: https://taxsummaries.pwc.com/poland/corporate/taxes-on-corporate-income | D11: 46207
A12: Peer trading multiples | B12: 2026E/2027E | C12: https://www.inderes.fi/files/869abfcd-d35a-4ae8-9ff7-9a2c58f5cd6c | D12: 46207
A13: FY2022 opening balance sheet | B13: FY2022 / opening balance | C13: https://ir.autopartner.com/wp-content/uploads/2023/09/Consolidated-financial-statements-for-the-year-ended-December-31st-2022_EN.pdf | D13: 46207

Sheet Assumptions
A1: Assumptions
A3: Metric | B3: 2023A | C3: 2024A | D3: 2025A | E3: 2026E | F3: 2027E | G3: 2028E | H3: 2029E | I3: 2030E | J3: Source / Rationale
A4: Revenue growth | B4: ='3Stmt'!C5 -> 0.28880753 | C4: ='3Stmt'!D5 -> 0.12566787 | D4: ='3Stmt'!E5 -> 0.075963095 | E4: 0.105 | F4: 0.08 | G4: 0.065 | H4: 0.055 | I4: 0.045 | J4: History from 3Stmt; forecast supported by 2026 YTD revenue growth and tapering scale.
A5: Gross margin | B5: ='3Stmt'!C8 -> 0.27094852 | C5: ='3Stmt'!D8 -> 0.27409649 | D5: ='3Stmt'!E8 -> 0.26556517 | E5: 0.275 | F5: 0.273 | G5: 0.272 | H5: 0.272 | I5: 0.272 | J5: History from 3Stmt; forecast assumes modest recovery from 2025 gross margin.
A6: EBITDA margin | B6: ='3Stmt'!C10 -> 0.094769124 | C6: ='3Stmt'!D10 -> 0.083539514 | D6: ='3Stmt'!E10 -> 0.076206554 | E6: 0.082 | F6: 0.083 | G6: 0.084 | H6: 0.085 | I6: 0.085 | J6: History from 3Stmt; forecast assumes margin recovery toward 8.5% EBITDA.
A7: D&A / Revenue | B7: ='3Stmt'!C11/'3Stmt'!C4 -> 0.011907864 | C7: ='3Stmt'!D11/'3Stmt'!D4 -> 0.013199766 | D7: ='3Stmt'!E11/'3Stmt'!E4 -> 0.012850022 | E7: 0.013 | F7: 0.013 | G7: 0.013 | H7: 0.013 | I7: 0.013 | J7: History from 3Stmt; forecast held near recent D&A intensity.
A8: Capex / Revenue | B8: =ABS('3Stmt'!C42)/'3Stmt'!C4 -> 0.010395568 | C8: =ABS('3Stmt'!D42)/'3Stmt'!D4 -> 0.011126573 | D8: =ABS('3Stmt'!E42)/'3Stmt'!E4 -> 0.0084808792 | E8: 0.013 | F8: 0.012 | G8: 0.011 | H8: 0.011 | I8: 0.011 | J8: History from 3Stmt; forecast capex normalizes after logistics investment phase. Review: may be low if expansion capex remains elevated.
A9: Cash / Revenue (output) | B9: ='3Stmt'!C21/'3Stmt'!C4 -> 0.010226136 | C9: ='3Stmt'!D21/'3Stmt'!D4 -> 0.0093821345 | D9: ='3Stmt'!E21/'3Stmt'!E4 -> 0.011658582 | E9: ='3Stmt'!F21/'3Stmt'!F4 -> 0.02 | F9: ='3Stmt'!G21/'3Stmt'!G4 -> 0.02 | G9: ='3Stmt'!H21/'3Stmt'!H4 -> 0.02 | H9: ='3Stmt'!I21/'3Stmt'!I4 -> 0.02 | I9: ='3Stmt'!J21/'3Stmt'!J4 -> 0.053140961 | J9: Output ratio after cash sweep and revised dividend policy; excess cash used for debt repayment until debt reaches zero.
A10: DSO days | B10: ='3Stmt'!C22/'3Stmt'!C4*365 -> 35.670029 | C10: ='3Stmt'!D22/'3Stmt'!D4*365 -> 37.355614 | D10: ='3Stmt'!E22/'3Stmt'!E4*365 -> 41.003959 | E10: 40.5 | F10: 40 | G10: 39.5 | H10: 39 | I10: 38.5 | J10: Historical DSO calculated from ending accounts receivable / revenue × 365. Forecast assumes gradual collection improvement toward 38.5 days.
A11: DIO days | B11: ='3Stmt'!C23/'3Stmt'!C6*365 -> 137.90999 | C11: ='3Stmt'!D23/'3Stmt'!D6*365 -> 136.95722 | D11: ='3Stmt'!E23/'3Stmt'!E6*365 -> 134.22787 | E11: 132 | F11: 130 | G11: 128 | H11: 127 | I11: 126 | J11: Historical DIO calculated from ending inventory / COGS × 365. Forecast assumes gradual inventory efficiency improvement toward 126 days.
A12: DPO days | B12: ='3Stmt'!C29/'3Stmt'!C6*365 -> 21.118434 | C12: ='3Stmt'!D29/'3Stmt'!D6*365 -> 17.746041 | D12: ='3Stmt'!E29/'3Stmt'!E6*365 -> 16.291585 | E12: 16.5 | F12: 16.8 | G12: 17 | H12: 17.2 | I12: 17.5 | J12: Historical DPO calculated from ending accounts payable / COGS × 365. Forecast assumes modest improvement in supplier payment terms.
A13: Other current assets / Revenue | B13: ='3Stmt'!C24/'3Stmt'!C4 -> 0.0056449035 | C13: ='3Stmt'!D24/'3Stmt'!D4 -> 0.0057923447 | D13: ='3Stmt'!E24/'3Stmt'!E4 -> 0.0049818131 | E13: 0.005 | F13: 0.005 | G13: 0.005 | H13: 0.005 | I13: 0.005 | J13: Historical ratio based on other current assets from 3Stmt; forecast held at 0.5% of revenue as a simplified operating working capital proxy.
A14: Other liabilities / Revenue | B14: ='3Stmt'!C31/'3Stmt'!C4 -> 0.02836384 | C14: ='3Stmt'!D31/'3Stmt'!D4 -> 0.02914993 | D14: ='3Stmt'!E31/'3Stmt'!E4 -> 0.029899693 | E14: 0.03 | F14: 0.03 | G14: 0.03 | H14: 0.03 | I14: 0.03 | J14: Historical ratio based on aggregated other liabilities from 3Stmt. Forecast held at 3.0% of revenue as a simplified working capital proxy; reported balance includes some tax, provision and employee-related liabilities.
A15: Tax rate | B15: ='3Stmt'!C16/'3Stmt'!C15 -> 0.1935727 | C15: ='3Stmt'!D16/'3Stmt'!D15 -> 0.19585508 | D15: ='3Stmt'!E16/'3Stmt'!E15 -> 0.19647783 | E15: 0.196 | F15: 0.196 | G15: 0.196 | H15: 0.196 | I15: 0.196 | J15: History calculated from taxes / EBT; forecast near FY2025 effective tax rate.
A16: Interest rate on prior-year debt | B16: ='3Stmt'!C14/'3Stmt'!B30 -> 0.050843228 | C16: ='3Stmt'!D14/'3Stmt'!C30 -> 0.062534694 | D16: ='3Stmt'!E14/'3Stmt'!D30 -> 0.062229759 | E16: 0.06 | F16: 0.06 | G16: 0.06 | H16: 0.06 | I16: 0.06 | J16: History calculated from interest / prior-year debt; forecast base cost of debt assumption.
A17: Dividend payout ratio | B17: =-'3Stmt'!C43/'3Stmt'!C17 -> 0.08763071 | C17: =-'3Stmt'!D43/'3Stmt'!D17 -> 0.094207986 | D17: =-'3Stmt'!E43/'3Stmt'!E17 -> 0.098490942 | E17: 0.1 | F17: 0.1 | G17: 0.1 | H17: 0.15 | I17: 0.25 | J17: Forecast assumes stable payout in near term, with gradual increase after deleveraging and stronger free cash flow generation.
A18: Minimum cash / Revenue | E18: 0.02 | F18: 0.02 | G18: 0.02 | H18: 0.02 | I18: 0.02 | J18: Minimum operating cash balance set at 2.0% of revenue. Excess cash is used in a simplified debt and lease liability sweep; bank debt and lease liabilities are not separately scheduled.
A20: Market & DCF Assumptions | B20: Value | C20: Source / Rationale
A21: Current share price | B21: 24.9 | C21: Auto Partner IR stock market info, as of 2026-06-30
A22: Shares outstanding | B22: 130.62 | C22: Auto Partner IR materials: 130,620,000 shares
A23: Market capitalization | B23: =B21*B22 -> 3252.438 | C23: Formula: share price x shares
A24: Q1 2026 gross debt & leases | B24: 501.6 | C24: Q1 2026 BS: borrowings + lease liabilities
A25: Q1 2026 cash | B25: 51.588 | C25: Q1 2026 BS cash and equivalents
A26: Net debt | B26: =B24-B25 -> 450.012 | C26: Gross debt & leases less cash
A27: Risk-free rate | B27: 0.0592 | C27: Poland 10Y government bond yield, 2026-06-30
A28: Equity risk premium | B28: 0.0475 | C28: Portfolio assumption; update with preferred ERP source
A29: Beta | B29: 0.9 | C29: Portfolio assumption for auto aftermarket distributor
A30: Size / liquidity premium | B30: 0.005 | C30: Portfolio assumption for WSE mid-cap liquidity
A31: Pre-tax cost of debt | B31: 0.06 | C31: Base case cost of debt assumption
A32: Debt weight | B32: =B24/(B23+B24) -> 0.13361612 | C32: Formula: gross debt / (market capitalization + gross debt)
A33: Cost of equity | B33: =B27+B29*B28+B30 -> 0.10695 | C33: CAPM + size / liquidity premium
A34: After-tax cost of debt | B34: =B31*(1-$E$15) -> 0.04824 | C34: Pre-tax cost of debt x (1 - tax rate)
A35: WACC | B35: =(1-B32)*B33+B32*B34 -> 0.099105397 | C35: Calculated from market capitalization and gross debt
A36: Terminal growth | B36: 0.03 | C36: Long-run nominal growth assumption

Sheet DCF
A1: Discounted Cash Flow Valuation
A2: PLN mm
A4: Year | B4: 2026E | C4: 2027E | D4: 2028E | E4: 2029E | F4: 2030E
A5: Revenue | B5: ='3Stmt'!F4 -> 4889.509 | C5: ='3Stmt'!G4 -> 5280.6697 | D5: ='3Stmt'!H4 -> 5623.9132 | E5: ='3Stmt'!I4 -> 5933.2285 | F5: ='3Stmt'!J4 -> 6200.2237
A6: EBIT | B6: ='3Stmt'!F12 -> 337.37612 | C6: ='3Stmt'!G12 -> 369.64688 | D6: ='3Stmt'!H12 -> 399.29784 | E6: ='3Stmt'!I12 -> 427.19245 | F6: ='3Stmt'!J12 -> 446.41611
A7: Tax Rate | B7: ='3Stmt'!F16/'3Stmt'!F15 -> 0.196 | C7: ='3Stmt'!G16/'3Stmt'!G15 -> 0.196 | D7: ='3Stmt'!H16/'3Stmt'!H15 -> 0.196 | E7: ='3Stmt'!I16/'3Stmt'!I15 -> 0.196 | F7: ='3Stmt'!J16/'3Stmt'!J15 -> 0.196
A8: NOPAT | B8: =B6*(1-B7) -> 271.2504 | C8: =C6*(1-C7) -> 297.19609 | D8: =D6*(1-D7) -> 321.03546 | E8: =E6*(1-E7) -> 343.46273 | F8: =F6*(1-F7) -> 358.91855
A9: D&A | B9: ='3Stmt'!F11 -> 63.563617 | C9: ='3Stmt'!G11 -> 68.648706 | D9: ='3Stmt'!H11 -> 73.110872 | E9: ='3Stmt'!I11 -> 77.13197 | F9: ='3Stmt'!J11 -> 80.602908
A10: Capex | B10: ='3Stmt'!F42 -> -63.563617 | C10: ='3Stmt'!G42 -> -63.368036 | D10: ='3Stmt'!H42 -> -61.863045 | E10: ='3Stmt'!I42 -> -65.265513 | F10: ='3Stmt'!J42 -> -68.202461
A11: Change in Working Capital | B11: ='3Stmt'!F40 -> 105.15327 | C11: ='3Stmt'!G40 -> 95.279946 | D11: ='3Stmt'!H40 -> 75.788388 | E11: ='3Stmt'!I40 -> 71.892363 | F11: ='3Stmt'!J40 -> 55.755035
A12: FCFF | B12: =B8+B9+B10-B11 -> 166.09713 | C12: =C8+C9+C10-C11 -> 207.19681 | D12: =D8+D9+D10-D11 -> 256.4949 | E12: =E8+E9+E10-E11 -> 283.43682 | F12: =F8+F9+F10-F11 -> 315.56396
A13: Discount Period | B13: 0.5 | C13: 1.5 | D13: 2.5 | E13: 3.5 | F13: 4.5
A14: Discount Factor | B14: =1/(1+Assumptions!$B$35)^B13 -> 0.95385054 | C14: =1/(1+Assumptions!$B$35)^C13 -> 0.86784265 | D14: =1/(1+Assumptions!$B$35)^D13 -> 0.78959002 | E14: =1/(1+Assumptions!$B$35)^E13 -> 0.71839336 | F14: =1/(1+Assumptions!$B$35)^F13 -> 0.65361644
A15: PV of FCFF | B15: =B12*B14 -> 158.43184 | C15: =C12*C14 -> 179.81423 | D15: =D12*D14 -> 202.52581 | E15: =E12*E14 -> 203.61913 | F15: =F12*F14 -> 206.25779
A17: Terminal Growth | B17: =Assumptions!B36 -> 0.03
A18: Terminal Value | B18: =F12*(1+B17)/(Assumptions!B35-B17) -> 4703.408
A19: PV of Terminal Value | B19: =B18*F14 -> 3074.2248
A20: Enterprise Value | B20: =SUM(B15:F15)+B19 -> 4024.8736
A21: Net Debt | B21: =Assumptions!B26 -> 450.012
A22: Equity Value | B22: =B20-B21 -> 3574.8616
A23: Shares Outstanding | B23: =Assumptions!B22 -> 130.62
A24: Implied Share Price - DCF | B24: =B22/B23 -> 27.368409
A25: Current Share Price | B25: =Assumptions!B21 -> 24.9
A26: Upside / (Downside) | B26: =B24/B25-1 -> 0.099132907
A30: DCF Sensitivity: Implied Share Price | C30: Terminal Growth
B31: WACC / g | C31: 0.02 | D31: 0.025 | E31: 0.03 | F31: 0.035 | G31: 0.04
B32: 0.08 | C32: =(SUM(B12/(1+$B32)^0.5,C12/(1+$B32)^1.5,D12/(1+$B32)^2.5,E12/(1+$B32)^3.5,F12/(1+$B32)^4.5)+(F12*(1+C$31)/($B32-C$31))/(1+$B32)^4.5-Assumptions!$B$26)/Assumptions!$B$22 -> 33.226187 | D32: =(SUM(B12/(1+$B32)^0.5,C12/(1+$B32)^1.5,D12/(1+$B32)^2.5,E12/(1+$B32)^3.5,F12/(1+$B32)^4.5)+(F12*(1+D$31)/($B32-D$31))/(1+$B32)^4.5-Assumptions!$B$26)/Assumptions!$B$22 -> 36.022273 | E32: =(SUM(B12/(1+$B32)^0.5,C12/(1+$B32)^1.5,D12/(1+$B32)^2.5,E12/(1+$B32)^3.5,F12/(1+$B32)^4.5)+(F12*(1+E$31)/($B32-E$31))/(1+$B32)^4.5-Assumptions!$B$26)/Assumptions!$B$22 -> 39.377577 | F32: =(SUM(B12/(1+$B32)^0.5,C12/(1+$B32)^1.5,D12/(1+$B32)^2.5,E12/(1+$B32)^3.5,F12/(1+$B32)^4.5)+(F12*(1+F$31)/($B32-F$31))/(1+$B32)^4.5-Assumptions!$B$26)/Assumptions!$B$22 -> 43.478505 | G32: =(SUM(B12/(1+$B32)^0.5,C12/(1+$B32)^1.5,D12/(1+$B32)^2.5,E12/(1+$B32)^3.5,F12/(1+$B32)^4.5)+(F12*(1+G$31)/($B32-G$31))/(1+$B32)^4.5-Assumptions!$B$26)/Assumptions!$B$22 -> 48.604664
B33: 0.085 | C33: =(SUM(B12/(1+$B33)^0.5,C12/(1+$B33)^1.5,D12/(1+$B33)^2.5,E12/(1+$B33)^3.5,F12/(1+$B33)^4.5)+(F12*(1+C$31)/($B33-C$31))/(1+$B33)^4.5-Assumptions!$B$26)/Assumptions!$B$22 -> 30.347218 | D33: =(SUM(B12/(1+$B33)^0.5,C12/(1+$B33)^1.5,D12/(1+$B33)^2.5,E12/(1+$B33)^3.5,F12/(1+$B33)^4.5)+(F12*(1+D$31)/($B33-D$31))/(1+$B33)^4.5-Assumptions!$B$26)/Assumptions!$B$22 -> 32.675197 | E33: =(SUM(B12/(1+$B33)^0.5,C12/(1+$B33)^1.5,D12/(1+$B33)^2.5,E12/(1+$B33)^3.5,F12/(1+$B33)^4.5)+(F12*(1+E$31)/($B33-E$31))/(1+$B33)^4.5-Assumptions!$B$26)/Assumptions!$B$22 -> 35.426445 | F33: =(SUM(B12/(1+$B33)^0.5,C12/(1+$B33)^1.5,D12/(1+$B33)^2.5,E12/(1+$B33)^3.5,F12/(1+$B33)^4.5)+(F12*(1+F$31)/($B33-F$31))/(1+$B33)^4.5-Assumptions!$B$26)/Assumptions!$B$22 -> 38.727942 | G33: =(SUM(B12/(1+$B33)^0.5,C12/(1+$B33)^1.5,D12/(1+$B33)^2.5,E12/(1+$B33)^3.5,F12/(1+$B33)^4.5)+(F12*(1+G$31)/($B33-G$31))/(1+$B33)^4.5-Assumptions!$B$26)/Assumptions!$B$22 -> 42.763106
B34: 0.09 | C34: =(SUM(B12/(1+$B34)^0.5,C12/(1+$B34)^1.5,D12/(1+$B34)^2.5,E12/(1+$B34)^3.5,F12/(1+$B34)^4.5)+(F12*(1+C$31)/($B34-C$31))/(1+$B34)^4.5-Assumptions!$B$26)/Assumptions!$B$22 -> 27.880931 | D34: =(SUM(B12/(1+$B34)^0.5,C12/(1+$B34)^1.5,D12/(1+$B34)^2.5,E12/(1+$B34)^3.5,F12/(1+$B34)^4.5)+(F12*(1+D$31)/($B34-D$31))/(1+$B34)^4.5-Assumptions!$B$26)/Assumptions!$B$22 -> 29.844488 | E34: =(SUM(B12/(1+$B34)^0.5,C12/(1+$B34)^1.5,D12/(1+$B34)^2.5,E12/(1+$B34)^3.5,F12/(1+$B34)^4.5)+(F12*(1+E$31)/($B34-E$31))/(1+$B34)^4.5-Assumptions!$B$26)/Assumptions!$B$22 -> 32.135305 | F34: =(SUM(B12/(1+$B34)^0.5,C12/(1+$B34)^1.5,D12/(1+$B34)^2.5,E12/(1+$B34)^3.5,F12/(1+$B34)^4.5)+(F12*(1+F$31)/($B34-F$31))/(1+$B34)^4.5-Assumptions!$B$26)/Assumptions!$B$22 -> 34.842634 | G34: =(SUM(B12/(1+$B34)^0.5,C12/(1+$B34)^1.5,D12/(1+$B34)^2.5,E12/(1+$B34)^3.5,F12/(1+$B34)^4.5)+(F12*(1+G$31)/($B34-G$31))/(1+$B34)^4.5-Assumptions!$B$26)/Assumptions!$B$22 -> 38.091429
B35: 0.095 | C35: =(SUM(B12/(1+$B35)^0.5,C12/(1+$B35)^1.5,D12/(1+$B35)^2.5,E12/(1+$B35)^3.5,F12/(1+$B35)^4.5)+(F12*(1+C$31)/($B35-C$31))/(1+$B35)^4.5-Assumptions!$B$26)/Assumptions!$B$22 -> 25.744759 | D35: =(SUM(B12/(1+$B35)^0.5,C12/(1+$B35)^1.5,D12/(1+$B35)^2.5,E12/(1+$B35)^3.5,F12/(1+$B35)^4.5)+(F12*(1+D$31)/($B35-D$31))/(1+$B35)^4.5-Assumptions!$B$26)/Assumptions!$B$22 -> 27.419467 | E35: =(SUM(B12/(1+$B35)^0.5,C12/(1+$B35)^1.5,D12/(1+$B35)^2.5,E12/(1+$B35)^3.5,F12/(1+$B35)^4.5)+(F12*(1+E$31)/($B35-E$31))/(1+$B35)^4.5-Assumptions!$B$26)/Assumptions!$B$22 -> 29.351822 | F35: =(SUM(B12/(1+$B35)^0.5,C12/(1+$B35)^1.5,D12/(1+$B35)^2.5,E12/(1+$B35)^3.5,F12/(1+$B35)^4.5)+(F12*(1+F$31)/($B35-F$31))/(1+$B35)^4.5-Assumptions!$B$26)/Assumptions!$B$22 -> 31.606236 | G35: =(SUM(B12/(1+$B35)^0.5,C12/(1+$B35)^1.5,D12/(1+$B35)^2.5,E12/(1+$B35)^3.5,F12/(1+$B35)^4.5)+(F12*(1+G$31)/($B35-G$31))/(1+$B35)^4.5-Assumptions!$B$26)/Assumptions!$B$22 -> 34.270544
B36: 0.1 | C36: =(SUM(B12/(1+$B36)^0.5,C12/(1+$B36)^1.5,D12/(1+$B36)^2.5,E12/(1+$B36)^3.5,F12/(1+$B36)^4.5)+(F12*(1+C$31)/($B36-C$31))/(1+$B36)^4.5-Assumptions!$B$26)/Assumptions!$B$22 -> 23.87678 | D36: =(SUM(B12/(1+$B36)^0.5,C12/(1+$B36)^1.5,D12/(1+$B36)^2.5,E12/(1+$B36)^3.5,F12/(1+$B36)^4.5)+(F12*(1+D$31)/($B36-D$31))/(1+$B36)^4.5-Assumptions!$B$26)/Assumptions!$B$22 -> 25.318969 | E36: =(SUM(B12/(1+$B36)^0.5,C12/(1+$B36)^1.5,D12/(1+$B36)^2.5,E12/(1+$B36)^3.5,F12/(1+$B36)^4.5)+(F12*(1+E$31)/($B36-E$31))/(1+$B36)^4.5-Assumptions!$B$26)/Assumptions!$B$22 -> 26.967184 | F36: =(SUM(B12/(1+$B36)^0.5,C12/(1+$B36)^1.5,D12/(1+$B36)^2.5,E12/(1+$B36)^3.5,F12/(1+$B36)^4.5)+(F12*(1+F$31)/($B36-F$31))/(1+$B36)^4.5-Assumptions!$B$26)/Assumptions!$B$22 -> 28.868971 | G36: =(SUM(B12/(1+$B36)^0.5,C12/(1+$B36)^1.5,D12/(1+$B36)^2.5,E12/(1+$B36)^3.5,F12/(1+$B36)^4.5)+(F12*(1+G$31)/($B36-G$31))/(1+$B36)^4.5-Assumptions!$B$26)/Assumptions!$B$22 -> 31.087723
B37: 0.105 | C37: =(SUM(B12/(1+$B37)^0.5,C12/(1+$B37)^1.5,D12/(1+$B37)^2.5,E12/(1+$B37)^3.5,F12/(1+$B37)^4.5)+(F12*(1+C$31)/($B37-C$31))/(1+$B37)^4.5-Assumptions!$B$26)/Assumptions!$B$22 -> 22.229641 | D37: =(SUM(B12/(1+$B37)^0.5,C12/(1+$B37)^1.5,D12/(1+$B37)^2.5,E12/(1+$B37)^3.5,F12/(1+$B37)^4.5)+(F12*(1+D$31)/($B37-D$31))/(1+$B37)^4.5-Assumptions!$B$26)/Assumptions!$B$22 -> 23.482121 | E37: =(SUM(B12/(1+$B37)^0.5,C12/(1+$B37)^1.5,D12/(1+$B37)^2.5,E12/(1+$B37)^3.5,F12/(1+$B37)^4.5)+(F12*(1+E$31)/($B37-E$31))/(1+$B37)^4.5-Assumptions!$B$26)/Assumptions!$B$22 -> 24.901598 | F37: =(SUM(B12/(1+$B37)^0.5,C12/(1+$B37)^1.5,D12/(1+$B37)^2.5,E12/(1+$B37)^3.5,F12/(1+$B37)^4.5)+(F12*(1+F$31)/($B37-F$31))/(1+$B37)^4.5-Assumptions!$B$26)/Assumptions!$B$22 -> 26.523858 | G37: =(SUM(B12/(1+$B37)^0.5,C12/(1+$B37)^1.5,D12/(1+$B37)^2.5,E12/(1+$B37)^3.5,F12/(1+$B37)^4.5)+(F12*(1+G$31)/($B37-G$31))/(1+$B37)^4.5-Assumptions!$B$26)/Assumptions!$B$22 -> 28.395697

Sheet Comps
A1: Comparable Company Valuation
A4: Company | B4: Ticker | C4: Notes | D4: EV/EBIT 2026E | E4: EV/EBIT 2027E | F4: P/E 2026E | G4: P/E 2027E | H4: Source
A5: Relais Group | B5: RELAIS.HE | C5: Aftermarket parts distributor | D5: 11.2 | E5: 10.8 | F5: 10.7 | G5: 10.4 | H5: Inderes
A6: Mekonomen | B6: MEKO.ST | C6: Nordic auto aftermarket | D6: 10.9 | E6: 9 | F6: 7.4 | G6: 6.2 | H6: Inderes
A7: Inter Cars | B7: CAR.WA | C7: CEE auto parts distributor | D7: 10.9 | E7: 9.6 | F7: 13.8 | G7: 12 | H7: Inderes
A8: Auto Partner | B8: APR.WA | C8: Target / market multiple | D8: 10.9 | E8: 9.5 | F8: 16.5 | G8: 12.8 | H8: Inderes
A10: Median Peers ex Auto Partner | D10: =MEDIAN(D5:D7) -> 10.9 | E10: =MEDIAN(E5:E7) -> 9.6 | F10: =MEDIAN(F5:F7) -> 10.7 | G10: =MEDIAN(G5:G7) -> 10.4
A14: Comparable Valuation
A16: 2026E EBIT | B16: ='3Stmt'!F12 -> 337.37612
A17: 2027E EBIT | B17: ='3Stmt'!G12 -> 369.64688
A18: 2026E Net Income | B18: ='3Stmt'!F17 -> 240.40763
A19: 2027E Net Income | B19: ='3Stmt'!G17 -> 269.48947
A20: Net Debt | B20: =Assumptions!B26 -> 450.012
A21: Shares Outstanding | B21: =Assumptions!B22 -> 130.62
A23: EV/EBIT 2026E Implied Share Price | B23: =(B16*$D$10-B20)/B21 -> 24.70822
A24: EV/EBIT 2027E Implied Share Price | B24: =(B17*$E$10-B20)/B21 -> 23.722233
A25: P/E 2026E Implied Share Price | B25: =B18*$F$10/B21 -> 19.693474
A26: P/E 2027E Implied Share Price | B26: =B19*$G$10/B21 -> 21.456825
A27: Average Comparable Implied Share Price | B27: =AVERAGE(B23:B26) -> 22.395188
A28: Current Share Price | B28: =Assumptions!B21 -> 24.9
A29: Upside / (Downside) | B29: =B27/B28-1 -> -0.10059486

Sheet Checks
A1: Model Checks
A3: Check | B3: Location | C3: Delta | D3: Status | E3: Notes
A4: Balance Sheet balances - 2022A | B4: 3Stmt row 35 | C4: ='3Stmt'!B35 -> 0 | D4: =IF(ABS(C4)<0.1,"PASS","FAIL") -> PASS | E4: Total assets less liabilities & equity
A5: Balance Sheet balances - 2023A | B5: 3Stmt row 35 | C5: ='3Stmt'!C35 -> 0 | D5: =IF(ABS(C5)<0.1,"PASS","FAIL") -> PASS | E5: Total assets less liabilities & equity
A6: Balance Sheet balances - 2024A | B6: 3Stmt row 35 | C6: ='3Stmt'!D35 -> 0 | D6: =IF(ABS(C6)<0.1,"PASS","FAIL") -> PASS | E6: Total assets less liabilities & equity
A7: Balance Sheet balances - 2025A | B7: 3Stmt row 35 | C7: ='3Stmt'!E35 -> 0 | D7: =IF(ABS(C7)<0.1,"PASS","FAIL") -> PASS | E7: Total assets less liabilities & equity
A8: Balance Sheet balances - 2026E | B8: 3Stmt row 35 | C8: ='3Stmt'!F35 -> 0 | D8: =IF(ABS(C8)<0.1,"PASS","FAIL") -> PASS | E8: Total assets less liabilities & equity
A9: Balance Sheet balances - 2027E | B9: 3Stmt row 35 | C9: ='3Stmt'!G35 -> 0 | D9: =IF(ABS(C9)<0.1,"PASS","FAIL") -> PASS | E9: Total assets less liabilities & equity
A10: Balance Sheet balances - 2028E | B10: 3Stmt row 35 | C10: ='3Stmt'!H35 -> 0 | D10: =IF(ABS(C10)<0.1,"PASS","FAIL") -> PASS | E10: Total assets less liabilities & equity
A11: Balance Sheet balances - 2029E | B11: 3Stmt row 35 | C11: ='3Stmt'!I35 -> 0 | D11: =IF(ABS(C11)<0.1,"PASS","FAIL") -> PASS | E11: Total assets less liabilities & equity
A12: Balance Sheet balances - 2030E | B12: 3Stmt row 35 | C12: ='3Stmt'!J35 -> 0 | D12: =IF(ABS(C12)<0.1,"PASS","FAIL") -> PASS | E12: Total assets less liabilities & equity
A13: Cash flow ties to cash - 2023A | B13: 3Stmt row 47 | C13: ='3Stmt'!C47 -> 0 | D13: =IF(ABS(C13)<0.1,"PASS","FAIL") -> PASS | E13: Cash flow statement ending cash less balance sheet cash
A14: Cash flow ties to cash - 2024A | B14: 3Stmt row 47 | C14: ='3Stmt'!D47 -> 0 | D14: =IF(ABS(C14)<0.1,"PASS","FAIL") -> PASS | E14: Cash flow statement ending cash less balance sheet cash
A15: Cash flow ties to cash - 2025A | B15: 3Stmt row 47 | C15: ='3Stmt'!E47 -> 0 | D15: =IF(ABS(C15)<0.1,"PASS","FAIL") -> PASS | E15: Cash flow statement ending cash less balance sheet cash
A16: Cash flow ties to cash - 2026E | B16: 3Stmt row 47 | C16: ='3Stmt'!F47 -> 0 | D16: =IF(ABS(C16)<0.1,"PASS","FAIL") -> PASS | E16: Cash flow statement ending cash less balance sheet cash
A17: Cash flow ties to cash - 2027E | B17: 3Stmt row 47 | C17: ='3Stmt'!G47 -> 0 | D17: =IF(ABS(C17)<0.1,"PASS","FAIL") -> PASS | E17: Cash flow statement ending cash less balance sheet cash
A18: Cash flow ties to cash - 2028E | B18: 3Stmt row 47 | C18: ='3Stmt'!H47 -> 0 | D18: =IF(ABS(C18)<0.1,"PASS","FAIL") -> PASS | E18: Cash flow statement ending cash less balance sheet cash
A19: Cash flow ties to cash - 2029E | B19: 3Stmt row 47 | C19: ='3Stmt'!I47 -> 0 | D19: =IF(ABS(C19)<0.1,"PASS","FAIL") -> PASS | E19: Cash flow statement ending cash less balance sheet cash
A20: Cash flow ties to cash - 2030E | B20: 3Stmt row 47 | C20: ='3Stmt'!J47 -> 0 | D20: =IF(ABS(C20)<0.1,"PASS","FAIL") -> PASS | E20: Cash flow statement ending cash less balance sheet cash
A21: DCF WACC > terminal growth | B21: DCF / Assumptions | C21: =Assumptions!B35-Assumptions!B36 -> 0.069105397 | D21: =IF(C21>0,"PASS","FAIL") -> PASS | E21: Terminal value formula valid
A22: DCF share price positive | B22: DCF!B24 | C22: =DCF!B24 -> 27.368409 | D22: =IF(C22>0,"PASS","FAIL") -> PASS | E22: Sanity check; DCF not yet final
A23: Sources documented | B23: Sources | C23: =COUNTA(Sources!A4:A13) -> 10 | D23: =IF(C23>=10,"PASS","WARN") -> PASS | E23: Core source log present

Sheet Dashboard
A1: Dashboard
A2: Historical: 2023A–2025A | Forecast: 2026E–2030E | Currency: PLN mm
